/home/user/webapp/app_complete.py:3612: PTBUserWarning: If 'per_message=False', 'CallbackQueryHandler' will not be tracked for every message. Read this FAQ entry to learn more about the per_* settings: https://github.com/python-telegram-bot/python-telegram-bot/wiki/Frequently-Asked-Questions#what-do-the-per_-settings-in-conversationhandler-do.
  return ConversationHandler(
/home/user/webapp/app_complete.py:3658: PTBUserWarning: If 'per_message=False', 'CallbackQueryHandler' will not be tracked for every message. Read this FAQ entry to learn more about the per_* settings: https://github.com/python-telegram-bot/python-telegram-bot/wiki/Frequently-Asked-Questions#what-do-the-per_-settings-in-conversationhandler-do.
  return ConversationHandler(
2025-09-09 05:31:19,894 - __main__ - INFO - üöÄ ÿ®ÿØÿ° ÿ™ÿ¥ÿ∫ŸäŸÑ FC 26 Smart Bot...
2025-09-09 05:31:19,894 - __main__ - INFO - ‚ú® ÿßŸÑŸÜÿ∏ÿßŸÖ ÿßŸÑÿ∞ŸÉŸä ŸÑŸÑÿ±ÿ≥ÿßÿ¶ŸÑ ŸÖŸÅÿπŸëŸÑ
2025-09-09 05:31:19,894 - __main__ - INFO - üì± ÿßŸÑÿ®Ÿàÿ™ ÿ¨ÿßŸáÿ≤: https://t.me/FC26_Trading_Bot
2025-09-09 05:31:22,152 - httpx - INFO - HTTP Request: POST https://api.telegram.org/bot7607085569:AAEDNKwt8j8B_CjG5gjKLJ8MLjrTRCCrx6k/getMe "HTTP/1.1 401 Unauthorized"
2025-09-09 05:31:22,153 - telegram.ext - ERROR - Network Retry Loop (Bootstrap Initialize Application): Invalid token. Aborting retry loop.
Traceback (most recent call last):
  File "/usr/local/lib/python3.12/site-packages/telegram/_bot.py", line 845, in initialize
    await self.get_me()
  File "/usr/local/lib/python3.12/site-packages/telegram/ext/_extbot.py", line 1981, in get_me
    return await super().get_me(
           ^^^^^^^^^^^^^^^^^^^^^
  File "/usr/local/lib/python3.12/site-packages/telegram/_bot.py", line 976, in get_me
    result = await self._post(
             ^^^^^^^^^^^^^^^^^
  File "/usr/local/lib/python3.12/site-packages/telegram/_bot.py", line 698, in _post
    return await self._do_post(
           ^^^^^^^^^^^^^^^^^^^^
  File "/usr/local/lib/python3.12/site-packages/telegram/ext/_extbot.py", line 370, in _do_post
    return await super()._do_post(
           ^^^^^^^^^^^^^^^^^^^^^^^
  File "/usr/local/lib/python3.12/site-packages/telegram/_bot.py", line 727, in _do_post
    result = await request.post(
             ^^^^^^^^^^^^^^^^^^^
  File "/usr/local/lib/python3.12/site-packages/telegram/request/_baserequest.py", line 197, in post
    result = await self._request_wrapper(
             ^^^^^^^^^^^^^^^^^^^^^^^^^^^^
  File "/usr/local/lib/python3.12/site-packages/telegram/request/_baserequest.py", line 374, in _request_wrapper
    raise exception
telegram.error.InvalidToken: Unauthorized

The above exception was the direct cause of the following exception:

Traceback (most recent call last):
  File "/usr/local/lib/python3.12/site-packages/telegram/ext/_utils/networkloop.py", line 115, in network_retry_loop
    if not await do_action():
           ^^^^^^^^^^^^^^^^^
  File "/usr/local/lib/python3.12/site-packages/telegram/ext/_utils/networkloop.py", line 93, in do_action
    return await action_cb()
           ^^^^^^^^^^^^^^^^^
  File "/usr/local/lib/python3.12/site-packages/telegram/ext/_application.py", line 489, in initialize
    await self.bot.initialize()
  File "/usr/local/lib/python3.12/site-packages/telegram/ext/_extbot.py", line 316, in initialize
    await super().initialize()
  File "/usr/local/lib/python3.12/site-packages/telegram/_bot.py", line 847, in initialize
    raise InvalidToken(f"The token `{self._token}` was rejected by the server.") from exc
telegram.error.InvalidToken: The token `7607085569:AAEDNKwt8j8B_CjG5gjKLJ8MLjrTRCCrx6k` was rejected by the server.
Traceback (most recent call last):
  File "/usr/local/lib/python3.12/site-packages/telegram/_bot.py", line 845, in initialize
    await self.get_me()
  File "/usr/local/lib/python3.12/site-packages/telegram/ext/_extbot.py", line 1981, in get_me
    return await super().get_me(
           ^^^^^^^^^^^^^^^^^^^^^
  File "/usr/local/lib/python3.12/site-packages/telegram/_bot.py", line 976, in get_me
    result = await self._post(
             ^^^^^^^^^^^^^^^^^
  File "/usr/local/lib/python3.12/site-packages/telegram/_bot.py", line 698, in _post
    return await self._do_post(
           ^^^^^^^^^^^^^^^^^^^^
  File "/usr/local/lib/python3.12/site-packages/telegram/ext/_extbot.py", line 370, in _do_post
    return await super()._do_post(
           ^^^^^^^^^^^^^^^^^^^^^^^
  File "/usr/local/lib/python3.12/site-packages/telegram/_bot.py", line 727, in _do_post
    result = await request.post(
             ^^^^^^^^^^^^^^^^^^^
  File "/usr/local/lib/python3.12/site-packages/telegram/request/_baserequest.py", line 197, in post
    result = await self._request_wrapper(
             ^^^^^^^^^^^^^^^^^^^^^^^^^^^^
  File "/usr/local/lib/python3.12/site-packages/telegram/request/_baserequest.py", line 374, in _request_wrapper
    raise exception
telegram.error.InvalidToken: Unauthorized

The above exception was the direct cause of the following exception:

Traceback (most recent call last):
  File "/home/user/webapp/app_complete.py", line 3788, in <module>
    bot.run()
  File "/home/user/webapp/app_complete.py", line 3783, in run
    app.run_polling(allowed_updates=Update.ALL_TYPES)
  File "/usr/local/lib/python3.12/site-packages/telegram/ext/_application.py", line 839, in run_polling
    return self.__run(
           ^^^^^^^^^^^
  File "/usr/local/lib/python3.12/site-packages/telegram/ext/_application.py", line 1049, in __run
    loop.run_until_complete(self._bootstrap_initialize(max_retries=bootstrap_retries))
  File "/usr/local/lib/python3.12/asyncio/base_events.py", line 691, in run_until_complete
    return future.result()
           ^^^^^^^^^^^^^^^
  File "/usr/local/lib/python3.12/site-packages/telegram/ext/_application.py", line 1014, in _bootstrap_initialize
    await network_retry_loop(
  File "/usr/local/lib/python3.12/site-packages/telegram/ext/_utils/networkloop.py", line 115, in network_retry_loop
    if not await do_action():
           ^^^^^^^^^^^^^^^^^
  File "/usr/local/lib/python3.12/site-packages/telegram/ext/_utils/networkloop.py", line 93, in do_action
    return await action_cb()
           ^^^^^^^^^^^^^^^^^
  File "/usr/local/lib/python3.12/site-packages/telegram/ext/_application.py", line 489, in initialize
    await self.bot.initialize()
  File "/usr/local/lib/python3.12/site-packages/telegram/ext/_extbot.py", line 316, in initialize
    await super().initialize()
  File "/usr/local/lib/python3.12/site-packages/telegram/_bot.py", line 847, in initialize
    raise InvalidToken(f"The token `{self._token}` was rejected by the server.") from exc
telegram.error.InvalidToken: The token `7607085569:AAEDNKwt8j8B_CjG5gjKLJ8MLjrTRCCrx6k` was rejected by the server.
